<?xml version="1.0" ?>
<!-- =================================================================================== -->
<!-- |    This document was autogenerated by xacro from ny_gen3_robot_description/ny_gen3_robot_description/ny_gen3_robot_reva_description/urdf/gen3_reva_robot.urdf.xacro | -->
<!-- |    EDITING THIS FILE BY HAND IS NOT RECOMMENDED                                 | -->
<!-- =================================================================================== -->
<robot name="ny_gen3_reva_robot">
  <!-- Coler Format-->
  <material name="White">
    <color rgba="1.0 1.0 1.0 1.0"/>
  </material>
  <material name="Black">
    <color rgba="0 0 0 1.0"/>
  </material>
  <!--ここまで記載フォーマット-->
  <!-- Fix robot to world -->
  <link name="world"/>
  <link name="base_link"/>
  <joint name="world2base" type="fixed">
    <parent link="world"/>
    <child link="base_link"/>
    <origin rpy="0 0 0" xyz="0 0 0"/>
  </joint>
  <link name="lowerbody_base_link">
    <visual>
      <geometry>
        <mesh filename="package://ny_gen3_robot_description/ny_gen3_robot_reva_description/meshes/AMR_LowerBody.stl"/>
      </geometry>
      <material name="White"/>
      <origin rpy="0 0 0" xyz="0 0 0"/>
    </visual>
    <collision>
      <geometry>
        <mesh filename="package://ny_gen3_robot_description/ny_gen3_robot_reva_description/meshes/AMR_LowerBody.stl"/>
      </geometry>
      <material name="White"/>
      <origin rpy="0 0 0" xyz="0 0 0"/>
    </collision>
  </link>
  <joint name="baselink_to_lowerbodybase" type="fixed">
    <child link="lowerbody_base_link"/>
    <parent link="base_link"/>
    <origin rpy="0 0 0" xyz="0 0 0"/>
  </joint>
  <link name="vertical_link"/>
  <joint name="vertical_joint" type="prismatic">
    <axis rpy="0 0 0" xyz="0 0 1"/>
    <limit effort="100.0" lower="-0.5" upper="0.0" velocity="0.4"/>
    <origin xyz="0.0875 0 0.871"/>
    <parent link="lowerbody_base_link"/>
    <child link="vertical_link"/>
  </joint>
  <link name="upperbody_base_link">
    <visual>
      <geometry>
        <mesh filename="package://ny_gen3_robot_description/ny_gen3_robot_reva_description/meshes/AMR_UpperBodyBase.stl"/>
      </geometry>
      <material name="White"/>
      <origin rpy="0 0 0" xyz="0 0 0"/>
    </visual>
    <collision>
      <geometry>
        <mesh filename="package://ny_gen3_robot_description/ny_gen3_robot_reva_description/meshes/AMR_UpperBodyBase.stl"/>
      </geometry>
      <material name="White"/>
      <origin rpy="0 0 0" xyz="0 0 0"/>
    </collision>
  </link>
  <joint name="vertical_to_upperbodybaselink" type="fixed">
    <child link="upperbody_base_link"/>
    <parent link="vertical_link"/>
    <origin rpy="0 0 0" xyz="0 0 0"/>
  </joint>
  <joint name="baselink_to_left_root" type="fixed">
    <child link="left_base_link"/>
    <parent link="vertical_link"/>
    <origin rpy="0 0 -1.57" xyz="0.06 0.075 0.216"/>
  </joint>
  <joint name="baselink_to_right_root" type="fixed">
    <child link="right_base_link"/>
    <parent link="vertical_link"/>
    <origin rpy="0 0 1.57" xyz="0.06 -0.075 0.216"/>
  </joint>
  <transmission name="$join1_trans">
    <type>transmission_interface/SimpleTransmission</type>
    <actuator name="joint1_motor">
      <hardwareInterface>hardware_interface/PositionJointInterface</hardwareInterface>
      <mechanicalReduction>1</mechanicalReduction>
    </actuator>
    <joint name="joint1">
      <hardwareInterface>hardware_interface/PositionJointInterface</hardwareInterface>
    </joint>
  </transmission>
  <transmission name="$join2_trans">
    <type>transmission_interface/SimpleTransmission</type>
    <actuator name="joint2_motor">
      <hardwareInterface>hardware_interface/PositionJointInterface</hardwareInterface>
      <mechanicalReduction>1</mechanicalReduction>
    </actuator>
    <joint name="joint2">
      <hardwareInterface>hardware_interface/PositionJointInterface</hardwareInterface>
    </joint>
  </transmission>
  <transmission name="$join3_trans">
    <type>transmission_interface/SimpleTransmission</type>
    <actuator name="joint3_motor">
      <hardwareInterface>hardware_interface/PositionJointInterface</hardwareInterface>
      <mechanicalReduction>1</mechanicalReduction>
    </actuator>
    <joint name="joint3">
      <hardwareInterface>hardware_interface/PositionJointInterface</hardwareInterface>
    </joint>
  </transmission>
  <transmission name="$join4_trans">
    <type>transmission_interface/SimpleTransmission</type>
    <actuator name="joint4_motor">
      <hardwareInterface>hardware_interface/PositionJointInterface</hardwareInterface>
      <mechanicalReduction>1</mechanicalReduction>
    </actuator>
    <joint name="joint4">
      <hardwareInterface>hardware_interface/PositionJointInterface</hardwareInterface>
    </joint>
  </transmission>
  <transmission name="$join5_trans">
    <type>transmission_interface/SimpleTransmission</type>
    <actuator name="joint5_motor">
      <hardwareInterface>hardware_interface/PositionJointInterface</hardwareInterface>
      <mechanicalReduction>1</mechanicalReduction>
    </actuator>
    <joint name="joint5">
      <hardwareInterface>hardware_interface/PositionJointInterface</hardwareInterface>
    </joint>
  </transmission>
  <transmission name="$join6_trans">
    <type>transmission_interface/SimpleTransmission</type>
    <actuator name="joint6_motor">
      <hardwareInterface>hardware_interface/PositionJointInterface</hardwareInterface>
      <mechanicalReduction>1</mechanicalReduction>
    </actuator>
    <joint name="joint6">
      <hardwareInterface>hardware_interface/PositionJointInterface</hardwareInterface>
    </joint>
  </transmission>
  <transmission name="$join7_trans">
    <type>transmission_interface/SimpleTransmission</type>
    <actuator name="joint7_motor">
      <hardwareInterface>hardware_interface/PositionJointInterface</hardwareInterface>
      <mechanicalReduction>1</mechanicalReduction>
    </actuator>
    <joint name="joint7">
      <hardwareInterface>hardware_interface/PositionJointInterface</hardwareInterface>
    </joint>
  </transmission>
  <!-- gazebo plugin -->
  <gazebo>
    <plugin filename="libgazebo_ros_control.so" name="gazebo_ros_control">
      <robotNamespace>/</robotNamespace>
    </plugin>
    <!--
    <plugin name="gazebo_ros_power_monitor_controller" filename="libgazebo_ros_power_monitor.so">
      <alwaysOn>true</alwaysOn>
      <updateRate>1.0</updateRate>
      <timeout>5</timeout>
      <powerStateTopic>power_state</powerStateTopic>
      <powerStateRate>10.0</powerStateRate>
      <fullChargeCapacity>87.78</fullChargeCapacity>     
      <dischargeRate>-474</dischargeRate>
      <chargeRate>525</chargeRate>
      <dischargeVoltage>15.52</dischargeVoltage>
      <chargeVoltage>16.41</chargeVoltage>
    </plugin>
-->
  </gazebo>
  <!-- rs007l start -->
  <!-- Link 0 -->
  <link name="left_base_link"/>
  <!-- Link 1 -->
  <joint name="left_joint1" type="revolute">
    <axis rpy="0 0 0" xyz="0 0 1"/>
    <limit effort="1000.0" lower="-3.141592653589793" upper="3.141592653589793" velocity="0.5235987755982988"/>
    <origin rpy="0 0 0" xyz="0 0 0.0"/>
    <parent link="left_base_link"/>
    <child link="left_link1"/>
    <dynamics damping="0.0" friction="0.0"/>
  </joint>
  <link name="left_link1">
    <visual>
      <geometry>
        <mesh filename="package://ny_gen3_arm_description/arms/reva/meshes/NG3A_JT1.stl"/>
      </geometry>
      <material name="White"/>
      <origin rpy="0 0 0" xyz="0 0 0"/>
    </visual>
    <collision>
      <geometry>
        <mesh filename="package://ny_gen3_arm_description/arms/reva/meshes/NG3A_JT1.stl"/>
      </geometry>
      <material name="White"/>
      <origin rpy="0 0 0" xyz="0 0 0"/>
    </collision>
    <inertial>
      <mass value="3.389"/>
      <inertia ixx="1.0" ixy="0.0" ixz="0.0" iyy="1.0" iyz="0.0" izz="1.0"/>
    </inertial>
  </link>
  <!-- Link 2 -->
  <joint name="left_joint2" type="revolute">
    <axis rpy="0 0 0" xyz="1 0 0"/>
    <limit effort="1000.0" lower="-2.356194490192345" upper="2.356194490192345" velocity="0.5235987755982988"/>
    <origin rpy="0 0 0" xyz="-0.071 0 0.122"/>
    <parent link="left_link1"/>
    <child link="left_link2"/>
    <dynamics damping="0.0" friction="0.0"/>
  </joint>
  <link name="left_link2">
    <visual>
      <geometry>
        <mesh filename="package://ny_gen3_arm_description/arms/reva/meshes/NG3A_JT2.stl"/>
      </geometry>
      <material name="White"/>
      <origin rpy="0 0 0" xyz="0 0 0"/>
    </visual>
    <collision>
      <geometry>
        <mesh filename="package://ny_gen3_arm_description/arms/reva/meshes/NG3A_JT2.stl"/>
      </geometry>
      <material name="White"/>
      <origin rpy="0 0 0" xyz="0 0 0"/>
    </collision>
    <inertial>
      <mass value="1.316"/>
      <inertia ixx="1.0" ixy="0.0" ixz="0.0" iyy="1.0" iyz="0.0" izz="1.0"/>
    </inertial>
  </link>
  <!-- Link 3 -->
  <joint name="left_joint3" type="revolute">
    <axis rpy="0 0 0" xyz="0 0 1"/>
    <limit effort="1000.0" lower="-2.7401669256310974" upper="2.7401669256310974" velocity="0.5235987755982988"/>
    <origin rpy="0 0 0" xyz="-0.076 0 -0.085"/>
    <parent link="left_link2"/>
    <child link="left_link3"/>
    <dynamics damping="0.0" friction="0.0"/>
  </joint>
  <link name="left_link3">
    <visual>
      <geometry>
        <mesh filename="package://ny_gen3_arm_description/arms/reva/meshes/NG3A_JT3.stl"/>
      </geometry>
      <material name="White"/>
      <origin rpy="0 0 0" xyz="0 0 0"/>
    </visual>
    <collision>
      <geometry>
        <mesh filename="package://ny_gen3_arm_description/arms/reva/meshes/NG3A_JT3.stl"/>
      </geometry>
      <material name="White"/>
      <origin rpy="0 0 0" xyz="0 0 0"/>
    </collision>
    <inertial>
      <mass value="1.879"/>
      <inertia ixx="1.0" ixy="0.0" ixz="0.0" iyy="1.0" iyz="0.0" izz="1.0"/>
    </inertial>
  </link>
  <!-- Link 4_1 -->
  <joint name="left_joint4" type="revolute">
    <axis rpy="0 0 0" xyz="1 0 0"/>
    <limit effort="1000.0" lower="-3.490658503988659" upper="3.490658503988659" velocity="0.5235987755982988"/>
    <origin rpy="0 0 0" xyz="0 0 -0.1915"/>
    <parent link="left_link3"/>
    <child link="left_link4"/>
    <dynamics damping="0.0" friction="0.0"/>
  </joint>
  <link name="left_link4">
    <visual>
      <geometry>
        <mesh filename="package://ny_gen3_arm_description/arms/reva/meshes/NG3A_JT4_LINK.stl"/>
      </geometry>
      <material name="White"/>
      <origin rpy="0 0 0" xyz="0 0 0"/>
    </visual>
    <collision>
      <geometry>
        <mesh filename="package://ny_gen3_arm_description/arms/reva/meshes/NG3A_JT4_LINK.stl"/>
      </geometry>
      <material name="White"/>
      <origin rpy="0 0 0" xyz="0 0 0"/>
    </collision>
    <inertial>
      <mass value="0.951"/>
      <inertia ixx="1.0" ixy="0.0" ixz="0.0" iyy="1.0" iyz="0.0" izz="1.0"/>
    </inertial>
  </link>
  <!-- Link 4_2 mimic -->
  <joint name="left_joint4_2" type="revolute">
    <mimic joint="left_joint4"/>
    <axis rpy="0 0 0" xyz="1 0 0"/>
    <limit effort="1000.0" lower="-3.490658503988659" upper="3.490658503988659" velocity="0.5235987755982988"/>
    <origin rpy="0 0 0" xyz="0 0 -0.0955"/>
    <parent link="left_link4"/>
    <child link="left_link4_2"/>
    <dynamics damping="0.0" friction="0.0"/>
  </joint>
  <link name="left_link4_2">
    <visual>
      <geometry>
        <mesh filename="package://ny_gen3_arm_description/arms/reva/meshes/NG3A_JT4.stl"/>
      </geometry>
      <material name="White"/>
      <origin rpy="0 0 0" xyz="0 0 0"/>
    </visual>
    <collision>
      <geometry>
        <mesh filename="package://ny_gen3_arm_description/arms/reva/meshes/NG3A_JT4.stl"/>
      </geometry>
      <material name="White"/>
      <origin rpy="0 0 0" xyz="0 0 0"/>
    </collision>
    <inertial>
      <mass value="1.019"/>
      <inertia ixx="1.0" ixy="0.0" ixz="0.0" iyy="1.0" iyz="0.0" izz="1.0"/>
    </inertial>
  </link>
  <!-- Link 5 -->
  <joint name="left_joint5" type="revolute">
    <axis rpy="0 0 0" xyz="0 0 1"/>
    <limit effort="1000.0" lower="-2.181661564992912" upper="2.181661564992912" velocity="0.5235987755982988"/>
    <origin rpy="0 0 1.57" xyz="0 0 -0.1375"/>
    <parent link="left_link4_2"/>
    <child link="left_link5"/>
    <dynamics damping="0.0" friction="0.0"/>
  </joint>
  <link name="left_link5">
    <visual>
      <geometry>
        <mesh filename="package://ny_gen3_arm_description/arms/reva/meshes/NG3A_JT5.stl"/>
      </geometry>
      <material name="White"/>
      <origin rpy="0 0 0" xyz="0 0 0"/>
    </visual>
    <collision>
      <geometry>
        <mesh filename="package://ny_gen3_arm_description/arms/reva/meshes/NG3A_JT5.stl"/>
      </geometry>
      <material name="White"/>
      <origin rpy="0 0 0" xyz="0 0 0"/>
    </collision>
    <inertial>
      <mass value="0.742"/>
      <inertia ixx="1.0" ixy="0.0" ixz="0.0" iyy="1.0" iyz="0.0" izz="1.0"/>
    </inertial>
  </link>
  <!-- Link 6 -->
  <joint name="left_joint6" type="revolute">
    <axis rpy="0 0 0" xyz="1 0 0"/>
    <limit effort="1000.0" lower="-6.283185307179586" upper="6.283185307179586" velocity="0.5235987755982988"/>
    <origin rpy="0 0 0" xyz="0 0 -0.1405"/>
    <parent link="left_link5"/>
    <child link="left_link6"/>
    <dynamics damping="0.0" friction="0.0"/>
  </joint>
  <link name="left_link6">
    <visual>
      <geometry>
        <mesh filename="package://ny_gen3_arm_description/arms/reva/meshes/NG3A_JT6.stl"/>
      </geometry>
      <material name="White"/>
      <origin rpy="0 0 3.1415" xyz="0 0 0"/>
    </visual>
    <collision>
      <geometry>
        <mesh filename="package://ny_gen3_arm_description/arms/reva/meshes/NG3A_JT6.stl"/>
      </geometry>
      <material name="White"/>
      <origin rpy="0 0 3.1415" xyz="0 0 0"/>
    </collision>
    <inertial>
      <mass value="0.238"/>
      <inertia ixx="1.0" ixy="0.0" ixz="0.0" iyy="1.0" iyz="0.0" izz="1.0"/>
    </inertial>
  </link>
  <!-- Link 7 -->
  <joint name="left_joint7" type="revolute">
    <axis rpy="0 0 0" xyz="0 1 0"/>
    <limit effort="1000.0" lower="-6.283185307179586" upper="6.283185307179586" velocity="0.5235987755982988"/>
    <origin rpy="0 0 3.141592" xyz="0 0.0245 -0.045"/>
    <parent link="left_link6"/>
    <child link="left_end_effector_link"/>
    <dynamics damping="0.0" friction="0.0"/>
  </joint>
  <link name="left_end_effector_link"/>
  <transmission name="$join1_trans">
    <type>transmission_interface/SimpleTransmission</type>
    <actuator name="joint1_motor">
      <hardwareInterface>hardware_interface/PositionJointInterface</hardwareInterface>
      <mechanicalReduction>1</mechanicalReduction>
    </actuator>
    <joint name="joint1">
      <hardwareInterface>hardware_interface/PositionJointInterface</hardwareInterface>
    </joint>
  </transmission>
  <transmission name="$join2_trans">
    <type>transmission_interface/SimpleTransmission</type>
    <actuator name="joint2_motor">
      <hardwareInterface>hardware_interface/PositionJointInterface</hardwareInterface>
      <mechanicalReduction>1</mechanicalReduction>
    </actuator>
    <joint name="joint2">
      <hardwareInterface>hardware_interface/PositionJointInterface</hardwareInterface>
    </joint>
  </transmission>
  <transmission name="$join3_trans">
    <type>transmission_interface/SimpleTransmission</type>
    <actuator name="joint3_motor">
      <hardwareInterface>hardware_interface/PositionJointInterface</hardwareInterface>
      <mechanicalReduction>1</mechanicalReduction>
    </actuator>
    <joint name="joint3">
      <hardwareInterface>hardware_interface/PositionJointInterface</hardwareInterface>
    </joint>
  </transmission>
  <transmission name="$join4_trans">
    <type>transmission_interface/SimpleTransmission</type>
    <actuator name="joint4_motor">
      <hardwareInterface>hardware_interface/PositionJointInterface</hardwareInterface>
      <mechanicalReduction>1</mechanicalReduction>
    </actuator>
    <joint name="joint4">
      <hardwareInterface>hardware_interface/PositionJointInterface</hardwareInterface>
    </joint>
  </transmission>
  <transmission name="$join5_trans">
    <type>transmission_interface/SimpleTransmission</type>
    <actuator name="joint5_motor">
      <hardwareInterface>hardware_interface/PositionJointInterface</hardwareInterface>
      <mechanicalReduction>1</mechanicalReduction>
    </actuator>
    <joint name="joint5">
      <hardwareInterface>hardware_interface/PositionJointInterface</hardwareInterface>
    </joint>
  </transmission>
  <transmission name="$join6_trans">
    <type>transmission_interface/SimpleTransmission</type>
    <actuator name="joint6_motor">
      <hardwareInterface>hardware_interface/PositionJointInterface</hardwareInterface>
      <mechanicalReduction>1</mechanicalReduction>
    </actuator>
    <joint name="joint6">
      <hardwareInterface>hardware_interface/PositionJointInterface</hardwareInterface>
    </joint>
  </transmission>
  <transmission name="$join7_trans">
    <type>transmission_interface/SimpleTransmission</type>
    <actuator name="joint7_motor">
      <hardwareInterface>hardware_interface/PositionJointInterface</hardwareInterface>
      <mechanicalReduction>1</mechanicalReduction>
    </actuator>
    <joint name="joint7">
      <hardwareInterface>hardware_interface/PositionJointInterface</hardwareInterface>
    </joint>
  </transmission>
  <!-- gazebo plugin -->
  <gazebo>
    <plugin filename="libgazebo_ros_control.so" name="gazebo_ros_control">
      <robotNamespace>/</robotNamespace>
    </plugin>
    <!--
    <plugin name="gazebo_ros_power_monitor_controller" filename="libgazebo_ros_power_monitor.so">
      <alwaysOn>true</alwaysOn>
      <updateRate>1.0</updateRate>
      <timeout>5</timeout>
      <powerStateTopic>power_state</powerStateTopic>
      <powerStateRate>10.0</powerStateRate>
      <fullChargeCapacity>87.78</fullChargeCapacity>     
      <dischargeRate>-474</dischargeRate>
      <chargeRate>525</chargeRate>
      <dischargeVoltage>15.52</dischargeVoltage>
      <chargeVoltage>16.41</chargeVoltage>
    </plugin>
-->
  </gazebo>
  <!-- rs007l start -->
  <!-- Link 0 -->
  <link name="right_base_link"/>
  <!-- Link 1 -->
  <joint name="right_joint1" type="revolute">
    <axis rpy="0 0 0" xyz="0 0 1"/>
    <limit effort="1000.0" lower="-3.141592653589793" upper="3.141592653589793" velocity="0.5235987755982988"/>
    <origin rpy="0 0 0" xyz="0 0 0.0"/>
    <parent link="right_base_link"/>
    <child link="right_link1"/>
    <dynamics damping="0.0" friction="0.0"/>
  </joint>
  <link name="right_link1">
    <visual>
      <geometry>
        <mesh filename="package://ny_gen3_arm_description/arms/reva/meshes/NG3A_JT1.stl"/>
      </geometry>
      <material name="White"/>
      <origin rpy="0 0 0" xyz="0 0 0"/>
    </visual>
    <collision>
      <geometry>
        <mesh filename="package://ny_gen3_arm_description/arms/reva/meshes/NG3A_JT1.stl"/>
      </geometry>
      <material name="White"/>
      <origin rpy="0 0 0" xyz="0 0 0"/>
    </collision>
    <inertial>
      <mass value="3.389"/>
      <inertia ixx="1.0" ixy="0.0" ixz="0.0" iyy="1.0" iyz="0.0" izz="1.0"/>
    </inertial>
  </link>
  <!-- Link 2 -->
  <joint name="right_joint2" type="revolute">
    <axis rpy="0 0 0" xyz="1 0 0"/>
    <limit effort="1000.0" lower="-2.356194490192345" upper="2.356194490192345" velocity="0.5235987755982988"/>
    <origin rpy="0 0 0" xyz="-0.071 0 0.122"/>
    <parent link="right_link1"/>
    <child link="right_link2"/>
    <dynamics damping="0.0" friction="0.0"/>
  </joint>
  <link name="right_link2">
    <visual>
      <geometry>
        <mesh filename="package://ny_gen3_arm_description/arms/reva/meshes/NG3A_JT2.stl"/>
      </geometry>
      <material name="White"/>
      <origin rpy="0 0 0" xyz="0 0 0"/>
    </visual>
    <collision>
      <geometry>
        <mesh filename="package://ny_gen3_arm_description/arms/reva/meshes/NG3A_JT2.stl"/>
      </geometry>
      <material name="White"/>
      <origin rpy="0 0 0" xyz="0 0 0"/>
    </collision>
    <inertial>
      <mass value="1.316"/>
      <inertia ixx="1.0" ixy="0.0" ixz="0.0" iyy="1.0" iyz="0.0" izz="1.0"/>
    </inertial>
  </link>
  <!-- Link 3 -->
  <joint name="right_joint3" type="revolute">
    <axis rpy="0 0 0" xyz="0 0 1"/>
    <limit effort="1000.0" lower="-2.7401669256310974" upper="2.7401669256310974" velocity="0.5235987755982988"/>
    <origin rpy="0 0 0" xyz="-0.076 0 -0.085"/>
    <parent link="right_link2"/>
    <child link="right_link3"/>
    <dynamics damping="0.0" friction="0.0"/>
  </joint>
  <link name="right_link3">
    <visual>
      <geometry>
        <mesh filename="package://ny_gen3_arm_description/arms/reva/meshes/NG3A_JT3.stl"/>
      </geometry>
      <material name="White"/>
      <origin rpy="0 0 0" xyz="0 0 0"/>
    </visual>
    <collision>
      <geometry>
        <mesh filename="package://ny_gen3_arm_description/arms/reva/meshes/NG3A_JT3.stl"/>
      </geometry>
      <material name="White"/>
      <origin rpy="0 0 0" xyz="0 0 0"/>
    </collision>
    <inertial>
      <mass value="1.879"/>
      <inertia ixx="1.0" ixy="0.0" ixz="0.0" iyy="1.0" iyz="0.0" izz="1.0"/>
    </inertial>
  </link>
  <!-- Link 4_1 -->
  <joint name="right_joint4" type="revolute">
    <axis rpy="0 0 0" xyz="1 0 0"/>
    <limit effort="1000.0" lower="-3.490658503988659" upper="3.490658503988659" velocity="0.5235987755982988"/>
    <origin rpy="0 0 0" xyz="0 0 -0.1915"/>
    <parent link="right_link3"/>
    <child link="right_link4"/>
    <dynamics damping="0.0" friction="0.0"/>
  </joint>
  <link name="right_link4">
    <visual>
      <geometry>
        <mesh filename="package://ny_gen3_arm_description/arms/reva/meshes/NG3A_JT4_LINK.stl"/>
      </geometry>
      <material name="White"/>
      <origin rpy="0 0 0" xyz="0 0 0"/>
    </visual>
    <collision>
      <geometry>
        <mesh filename="package://ny_gen3_arm_description/arms/reva/meshes/NG3A_JT4_LINK.stl"/>
      </geometry>
      <material name="White"/>
      <origin rpy="0 0 0" xyz="0 0 0"/>
    </collision>
    <inertial>
      <mass value="0.951"/>
      <inertia ixx="1.0" ixy="0.0" ixz="0.0" iyy="1.0" iyz="0.0" izz="1.0"/>
    </inertial>
  </link>
  <!-- Link 4_2 mimic -->
  <joint name="right_joint4_2" type="revolute">
    <mimic joint="right_joint4"/>
    <axis rpy="0 0 0" xyz="1 0 0"/>
    <limit effort="1000.0" lower="-3.490658503988659" upper="3.490658503988659" velocity="0.5235987755982988"/>
    <origin rpy="0 0 0" xyz="0 0 -0.0955"/>
    <parent link="right_link4"/>
    <child link="right_link4_2"/>
    <dynamics damping="0.0" friction="0.0"/>
  </joint>
  <link name="right_link4_2">
    <visual>
      <geometry>
        <mesh filename="package://ny_gen3_arm_description/arms/reva/meshes/NG3A_JT4.stl"/>
      </geometry>
      <material name="White"/>
      <origin rpy="0 0 0" xyz="0 0 0"/>
    </visual>
    <collision>
      <geometry>
        <mesh filename="package://ny_gen3_arm_description/arms/reva/meshes/NG3A_JT4.stl"/>
      </geometry>
      <material name="White"/>
      <origin rpy="0 0 0" xyz="0 0 0"/>
    </collision>
    <inertial>
      <mass value="1.019"/>
      <inertia ixx="1.0" ixy="0.0" ixz="0.0" iyy="1.0" iyz="0.0" izz="1.0"/>
    </inertial>
  </link>
  <!-- Link 5 -->
  <joint name="right_joint5" type="revolute">
    <axis rpy="0 0 0" xyz="0 0 1"/>
    <limit effort="1000.0" lower="-2.181661564992912" upper="2.181661564992912" velocity="0.5235987755982988"/>
    <origin rpy="0 0 -1.57" xyz="0 0 -0.1375"/>
    <parent link="right_link4_2"/>
    <child link="right_link5"/>
    <dynamics damping="0.0" friction="0.0"/>
  </joint>
  <link name="right_link5">
    <visual>
      <geometry>
        <mesh filename="package://ny_gen3_arm_description/arms/reva/meshes/NG3A_JT5.stl"/>
      </geometry>
      <material name="White"/>
      <origin rpy="0 0 0" xyz="0 0 0"/>
    </visual>
    <collision>
      <geometry>
        <mesh filename="package://ny_gen3_arm_description/arms/reva/meshes/NG3A_JT5.stl"/>
      </geometry>
      <material name="White"/>
      <origin rpy="0 0 0" xyz="0 0 0"/>
    </collision>
    <inertial>
      <mass value="0.742"/>
      <inertia ixx="1.0" ixy="0.0" ixz="0.0" iyy="1.0" iyz="0.0" izz="1.0"/>
    </inertial>
  </link>
  <!-- Link 6 -->
  <joint name="right_joint6" type="revolute">
    <axis rpy="0 0 0" xyz="1 0 0"/>
    <limit effort="1000.0" lower="-6.283185307179586" upper="6.283185307179586" velocity="0.5235987755982988"/>
    <origin rpy="0 0 0" xyz="0 0 -0.1405"/>
    <parent link="right_link5"/>
    <child link="right_link6"/>
    <dynamics damping="0.0" friction="0.0"/>
  </joint>
  <link name="right_link6">
    <visual>
      <geometry>
        <mesh filename="package://ny_gen3_arm_description/arms/reva/meshes/NG3A_JT6.stl"/>
      </geometry>
      <material name="White"/>
      <origin rpy="0 0 0" xyz="0 0 0"/>
    </visual>
    <collision>
      <geometry>
        <mesh filename="package://ny_gen3_arm_description/arms/reva/meshes/NG3A_JT6.stl"/>
      </geometry>
      <material name="White"/>
      <origin rpy="0 0 0" xyz="0 0 0"/>
    </collision>
    <inertial>
      <mass value="0.238"/>
      <inertia ixx="1.0" ixy="0.0" ixz="0.0" iyy="1.0" iyz="0.0" izz="1.0"/>
    </inertial>
  </link>
  <!-- Link 7 -->
  <joint name="right_joint7" type="revolute">
    <axis rpy="0 0 0" xyz="0 1 0"/>
    <limit effort="1000.0" lower="-6.283185307179586" upper="6.283185307179586" velocity="0.5235987755982988"/>
    <origin rpy="0 0 0" xyz="0 -0.0245 -0.045"/>
    <parent link="right_link6"/>
    <child link="right_end_effector_link"/>
    <dynamics damping="0.0" friction="0.0"/>
  </joint>
  <link name="right_end_effector_link"/>
</robot>

