<?xml version="1.0"?>
<robot xmlns:xacro="http://ros.org/wiki/xacro">
  <xacro:macro name="cafehand" params="prefix">

    <!-- joint limits [rad] -->
    <xacro:property name="thumb_lower_limit" value="${radians(-10)}"/>
    <xacro:property name="thumb_upper_limit" value="${radians(180)}"/>
    
    <!-- joint verocity limits [rad/s] -->
    <xacro:property name="thumb_velocity_limit" value="${radians( 30)}"/>

    <!-- gripper base -->
    <joint name="${prefix}gripper_base_joint" type="fixed">
      <axis xyz="0 0 1" rpy="0 0 0" />
      <origin xyz="0 0 0" rpy="0 0 0" />
      <parent link="${prefix}end_effector_link"/>
      <child link="${prefix}gripper_base_link"/>
    </joint>

    <link name="${prefix}gripper_base_link">
      <visual>
        <geometry>
          <mesh filename="package://ny_gen3_arm_description/grippers/cafehand/meshes/cafe_hand_base.stl"/>
        </geometry>
        <material name="White"/>
        <origin rpy="0 0 0" xyz="0 0 0"/>
      </visual>
      <collision>
        <geometry>
          <mesh filename="package://ny_gen3_arm_description/grippers/cafehand/meshes/cafe_hand_base.stl"/>
        </geometry>
        <material name="White"/>
        <origin rpy="0 0 0" xyz="0 0 0"/>
      </collision>
    </link> 
    
    <!-- thumb finger -->
    <joint name="${prefix}gripper_thumb" type="prismatic">
      <axis xyz="-1 0 0" rpy="0 0 0" />
      <limit effort="1000.0" lower="${thumb_lower_limit}" upper="${thumb_upper_limit}" velocity="${thumb_velocity_limit}"/>
      <origin xyz="0.0 -0.119 -0.0325" rpy="1.3 0 0" />
      <parent link="${prefix}gripper_base_link"/>
      <child link="${prefix}thumb_link"/>
    </joint>

    <link name="${prefix}thumb_link">
      <visual>
        <geometry>
          <mesh filename="package://ny_gen3_arm_description/grippers/cafehand/meshes/cafe_hand_move.stl"/>
        </geometry>
        <material name="White"/>
        <origin rpy="0 0 0" xyz="0 0 0"/>
      </visual>
    </link> 
  </xacro:macro>
</robot>

